Workbook
Name CarteirasMatrizAtivos12: config.carteiras!$FQ$7:$FV$106
Name CarteirasLista: carteiras.!$AA$6:$AA$20
Name CarteirasPerfil1: config.carteiras!$M$4
Name CarteirasNome12: config.carteiras!$FV$2
Name CarteirasNomeAbreviado15: config.carteiras!$HO$3
Name CarteirasMatrizAtivosCompleta3: config.carteiras!$AJ$7:$AX$106
Name CarteirasAtivos: carteiras.!$A$4:$L$264
Name CarteirasPerfil7: config.carteiras!$CY$4
Name CarteirasMatrizAtivosCompleta7: config.carteiras!$CR$7:$DF$106
Name ParametrosURL: carteiras.!$AK$2
Name IFIXCHANGE: 'portfólio'!$BR$81
Name IBOVCHANGEHISTORICO: 'portfólio'!$BU$87:$BU$96
Name CarteirasNome4: config.carteiras!$BF$2
Name CarteirasPerfil8: config.carteiras!$DN$4
Name CarteirasListaCriadasAbreviada: carteiras.!$AF$6:$AF$15
Name IFIXPRICE: 'portfólio'!$BQ$81
Name CarteirasNomeAbreviado7: config.carteiras!$CY$3
Name CarteirasNomeAbreviado3: config.carteiras!$AQ$3
Name AtivosLista: carteiras.!$AH$5:$AH$264
Name PortfolioOrdenarMatriz: config.books!$CX$5:$DG$574
Name PortfolioAtivosNovos: config.books!$X$5:$X$574
Name CarteirasPerfil9: config.carteiras!$EC$4
Name IBOVPRICE: 'portfólio'!$BQ$80
Name CarteirasNome6: config.carteiras!$CJ$2
Name CarteirasNome2: config.carteiras!$AB$2
Name CarteirasMatrizAtivos3: config.carteiras!$AL$7:$AQ$106
Name CarteirasMatrizAtivos15: config.carteiras!$HJ$7:$HO$106
Name CarteirasMatrizAtivos10: config.carteiras!$EM$7:$ER$106
Name CarteirasMatrizAtivosCompleta4: config.carteiras!$AY$7:$BM$106
Name CarteirasMatrizAtivos2: config.carteiras!$W$7:$AB$106
Name ParametrosIDAbaCarteira: carteiras.!$AK$3
Name CarteirasNome9: config.carteiras!$EC$2
Name CarteirasNome14: config.carteiras!$GZ$2
Name CarteirasNomeAbreviado10: config.carteiras!$ER$3
Name CarteirasAtivosEncerrados: carteiras.!$N$4:$Y$264
Name CarteirasNomeAbreviado4: config.carteiras!$BF$3
Name CarteirasMatrizAtivos8: config.carteiras!$DI$7:$DN$106
Name CarteirasListaCriadasPerfis: carteiras.!$AG$6:$AG$15
Name IBOVCHANGE: 'portfólio'!$BR$80
Name CarteirasMatrizAtivos11: config.carteiras!$FB$7:$FG$106
Name PortfolioOrdenarAtivos: config.books!$CU$5:$CU$574
Name CarteirasMatrizAtivos5: config.carteiras!$BP$7:$BU$106
Name CarteirasNomeAbreviado13: config.carteiras!$GK$3
Name CarteirasNomeAbreviado14: config.carteiras!$GZ$3
Name IBOVCHANGEPCT: 'portfólio'!$BS$80
Name CarteirasMatrizAtivosCompleta14: config.carteiras!$GS$7:$HG$106
Name CarteirasNome15: config.carteiras!$HO$2
Name CarteirasPerfil5: config.carteiras!$BU$4
Name ParametrosVersaoPlanilhaLancada: carteiras.!$AK$4
Name CarteirasPerfil11: config.carteiras!$FG$4
Name CarteirasNomeAbreviado11: config.carteiras!$FG$3
Name CarteirasPerfil13: config.carteiras!$GK$4
Name CarteirasPerfil14: config.carteiras!$GZ$4
Name CarteirasQuantidadeCriadas: carteiras.!$AE$4
Name CarteirasMatrizAtivosCompleta9: config.carteiras!$DV$7:$EJ$106
Name AtivosDados: portfolio.!$A$4:$BP$303
Name CarteirasMatrizAtivosCompleta8: config.carteiras!$DG$7:$DU$106
Name CarteirasNome5: config.carteiras!$BU$2
Name CarteirasListaCriadas: carteiras.!$AE$6:$AE$15
Name CarteirasMatrizAtivosCompleta13: config.carteiras!$GD$7:$GR$106

Sheet leiame
A2: PLANILHA DE CONTROLE E GESTÃO DE INVESTIMENTOS
A3: dlombello®planilhas
A5: Esta planilha é desenvolvida e mantida por dlombello planilhas em parceria com mdiemer planilhas
A6: Versão: | B6: v6.4.02
A7: Última Versão Disponível: | B7: =IF($B$6<carteiras.!$AK$4,"Existe(m) atualização(ões). A última versão é "&carteiras.!AK4&". Acesse o menu dlombello -> Verificar atualizações",carteiras.!AK4)
A8: Download: | B8: https://www.dlombelloplanilhas.com
A9: URL da Dlombello de origem
A10: URL da DiemerPlanilhas
A11: Essa planilha foi criada para auxiliá-lo no gerenciamento da sua carteira de investimentos de forma online e atualizada. As informações devem ser utilizadas apenas para fins informativos, toda e qualquer informação da planilha não devem ser usadas para fins fiscais. NÃO SOLICITAR EDIÇÃO!!! FAVOR LEIA O MANUAL E INSTRUÇÕES DE USO PELO LINK ABAIXO!
B12: PLAYLIST DE VÍDEOS DE INSTRUÇÃO DE USO
A13: Assista os vídeos 2x rápido | B13: https://www.youtube.com/c/dlombelloplanilhas/playlists
A14: Manual com vídeos | B14: https://www.dlombelloplanilhas.com/faq/faq-ebook
B15: DOAÇÕES PARA DESENVOLVIMENTO E MANUTENÇÃO DO PROJETO
A16: Desenvolvedores | B16: Douglas Alves Lombello, Maglan Cristiano Diemer e Mouriac Halen Diemer
B17: Caso a planilha lhe seja útil e queira incentivar a manutenção e criação de novas ferramentas, avalie ser um usuário Alpha!
A18: WebApp | B18: Conhece nosso WebApp
B19: app.dlombelloplanilhas.com
A20: Usuário Alpha | B20: =HYPERLINK("https://www.dlombelloplanilhas.com/planos","https://www.dlombelloplanilhas.com/planos") -> https://www.dlombelloplanilhas.com/planos
B22: INFORMAÇÕES COMPLEMENTARES
A23: Site | B23: A planilha está em constante atualização, afim de melhorias e correções de possíveis problemas. A versão mais atual estará sempre disponível pelo link abaixo:
B24: dlombelloplanilhas.com
A25: Formulário Suporte | B25: Dúvidas, críticas ou sugestões entre em contato pelo formulário:
B26: bit.ly/suporte_dlombelloplanilhas
A27: Discord | B27: Grupo de usuários e suporte no Discord:
B28: https://discord.gg/UFvrHgGQ5A
A29: Facebook | B29: Grupo de usuários no Facebook:
B30: https://www.facebook.com/groups/dlombelloplanilhas
A31: Telegram | B31: Grupo de usuários no Telegram:
B32: https://t.me/dlombelloplanilhas
A33: YouTube | B33: Se inscreva no canal do YouTube e ative as notificações:
B34: https://www.youtube.com/channel/UCYOmBs3ppKsfvm6TVfnkXUQ
B35: FONTE DE DADOS EXTERNOS :
A36: Google | B36: google.com/finance
A37: Funds Explorer | B37: =HYPERLINK("www.fundsexplorer.com.br","fundsexplorer.com.br") -> fundsexplorer.com.br
A38: Fundamentus | B38: fundamentus.com.br
A39: Versão | B39: HISTÓRICO DE ATUALIZAÇÕES
A40: v6.0 | B40: Versão inicial de testes de funções básicas
A41: v6.1 | B41: Versão completa homologada
A42: v6.2 | B42: Atualizações na aba alocação, caixa, gráficos, inclusão das abas Darf e Dirpf
B43: Obrigado e bons investimentos!!!

Sheet portfólio
B1: =NOW() -> 46092.901 | M1: =HYPERLINK("bit.ly/dlombelloplanilhas","dlombello®planilhas "&leiame!B6) -> dlombello®planilhas v6.4.02 | Q1: =image("https://lh3.googleusercontent.com/fife/ABSRlIoRwkeqx455dMEAYIU3xM0jhiUWm9uF-SD8X-Y9BIuGyWBXBzbKRightO43rRoubfFk-TFbf_xIiuBaYvAW1dxafrf53XjdNoAN3pQzhDpBGay5lR8Na1lz6HsodfG-8o8Pnde0ca6e0rgrocdmN_xaCzfb5w0EhjEVhqAXuuzbPjcBPGos2EoF8Ftmiy1oCDFF0BND-SYre6Yvd3OC"&"QFkx-bgLzPG2Ex8Qaq2V7fuLzPsBNpeNYlvatsHS2tqct-7DTs_CGURMTvFAIG6oCs02BPqK64Gjlby59YLyTSuX1leLv2nU3inB_mwaV9vvTpvCIbH2HugPP13V6gQNVMysPsqY8snYckzDe1ko1i-LSOA9tfUJMJTYzSO0emPxZ8k4CdrYvWKg1WvNQbR8fbrrq0K6Nb8YEWBsbVJQjBQ0aaJlj9zXg3vxrdgQTpo5pj8at-L8Ddw488HtYnT"&"PepdXIphaOgX_BGK2oytIxUG8-L17hq9DrH7t8kLnnNA1qabqHJbAwjDU1fmbvBtHrL4Mm-XCkv5JnziYdMj1V6IcDFRLFnnTCM70VkTP0vZlde2BGbfonjDeANHP3128HQVVZ7mZgeGZ_WZGbPjOI8WdZh9N0ZGcOwDqDIdnSE3O37DgjFLA_U_NbruqnDmLZPDpoRGEhXB1T5Tn42k3yPtGErHfdNQKLxEnNqDkV7DsRj8wsj3Lvryo9fu-lZ"&"UiW3QtuiXOgBjS=ft") | R1: painel composição do portfólio | AN1: INDICADORES COMPLEMENTARES
Q2: =HYPERLINK("https://sites.google.com/view/diemerplanilhas/Videos","youtube") -> youtube
B4: SELIC | D4: iGP-M | F4: IPCA | H4: INPC | J4: USDBRL | M4: ="Você tem o plano: "&IF('config.parâmetros'!O2="GRATUITO","GRATUITO", IF('config.parâmetros'!O2="","<aguarde leitura, tecle F5>", IF(MID('config.parâmetros'!O2,1,10)="UALN_001_2","PREMIUM", IF(MID('config.parâmetros'!O2,1,10)="UALN_001_I","ULTIMATE", IF(MID('config.parâmetros'!O2,1,10)="STARTER_01","STARTER", IF(MID('config.parâmetros'!O2,1,10)="PREMIUM_01","PREMIUM", IF(MID('config.parâmetros'!O2,1,10)="ULTIMATE_0","ULTIMATE", IF(MID('config.parâmetros'!O2,1,10)="MULTI_03_L","MULTI INVESTIDOR", IF(MID('config.parâmetros'!O2,1,10)="MULTI_05_L","MULTI INVESTIDOR","PERSONALIZADO"))))))))) -> Você tem o plano: <aguarde leitura, tecle F5> | Q4: =IF(AV11,"INVESTIDOR ▶","Conheça ▶") -> Conheça ▶ | R4: TRUE | S4: =IF(NOT(AV11)," Carteiras",IF('config.parâmetros'!B17="","","Investidor "&'config.parâmetros'!B17)) -> Carteiras | U4: TRUE | V4: =IF(NOT(AV11)," Books",IF('config.parâmetros'!B18="","","Investidor "&'config.parâmetros'!B18)) -> Books | X4: TRUE | Y4: =IF(NOT(AV11),"Multi investidor",IF('config.parâmetros'!B19="","","Investidor "&'config.parâmetros'!B19)) -> Multi investidor | AA4: TRUE | AB4: =IF(NOT(AV11)," Summary",IF('config.parâmetros'!B20="","","Investidor "&'config.parâmetros'!B20)) -> Summary | AD4: TRUE | AE4: =IF(NOT(AV11),"DARF/DIRF",IF('config.parâmetros'!B21="","","Investidor "&'config.parâmetros'!B21)) -> DARF/DIRF | AG4: TRUE | AH4: =IF(NOT(AV11),"Sistema Web",IF('config.parâmetros'!B22="","","Investidor "&'config.parâmetros'!B22)) -> Sistema Web | AJ4: TRUE | AK4: =IF(NOT(AV11)," Caixa",IF('config.parâmetros'!B23="","","Investidor "&'config.parâmetros'!B23)) -> Caixa | AN4: INDICADOR | AO4: Cotação | AP4: % dia | AQ4: =CONCATENATE("% ",$AS$4," dias") -> % 30 dias | AR4: Dias do gráfico: | AS4: 30
B5: 0.1275 | D5: 0.52% | F5: 1.06% | H5: +1,04% | J5: =BT81 -> 5.1928009
M6: PORTFÓLIO | Q6: TOTAL | T6: Lucro do dia | U6: Principais operações | AB6: Operações com fundos e Renda Fixa | AH6: Demais Operações | AK6: Rentabilidade geral | AN6: IBOV | AO6: =IBOVPRICE -> 183969.34 | AP6: =IF(NOT(ConfigOn),"",IBOVCHANGEPCT/100) -> 0.0028 | AQ6: =IFERROR(__xludf.DUMMYFUNCTION("IF(NOT(ConfigOn),"""",IFERROR(AO6/INDEX(IFERROR(GOOGLEFINANCE(""INDEXBVMF:""&AN6,""price"",TODAY()-$AS$4,TODAY(),1),IFERROR(GOOGLEFINANCE(""BVMF:""&AN6,""price"",TODAY()-$AS$4,TODAY(),1),GOOGLEFINANCE(AN6,""price"",TODAY()-$AS$4,TODAY(),1))),2,2)-1))"),-0.012198217203877815) -> -0.012198217 | AR6: =IFERROR(__xludf.DUMMYFUNCTION("IF(NOT(ConfigOn),"""",IFERROR(SPARKLINE(GOOGLEFINANCE(""INDEXBVMF:""&AN6,""price"",TODAY()-$AS$4,TODAY()))))"),"") | AV6: Ativado?
B7: LTN-23 | D7: LTN-26 | F7: NTNB-26 | H7: NTNB-35 | J7: NTNB-45 | Q7: Investido | R7: Atual | S7: Lucro | U7: Investido | V7: Atual | W7: Lucro Aberto | X7: Swing Trades | Y7: Day Trades | Z7: Proventos | AA7: Lucro total | AB7: Investido | AC7: Atual | AD7: Lucro Aberto | AE7: Trades | AF7: Proventos | AG7: Lucro total | AH7: Investido | AI7: Atual | AJ7: Lucro total | AK7: TIR am% | AL7: TIR aa% | AN7: IFIX | AO7: =IFIXPRICE -> 3873.59 | AP7: =IF(NOT(ConfigOn),"",IFIXCHANGEPCT/100) -> -0.0007 | AQ7: =IFERROR(__xludf.DUMMYFUNCTION("IF(NOT(ConfigOn),"""",IFERROR(AO7/INDEX(IFERROR(GOOGLEFINANCE(""INDEXBVMF:""&AN7,""price"",TODAY()-$AS$4,TODAY(),1),IFERROR(GOOGLEFINANCE(""BVMF:""&AN7,""price"",TODAY()-$AS$4,TODAY(),1),GOOGLEFINANCE(AN7,""price"",TODAY()-$AS$4,TODAY(),1))),2,2)-1))"),0.007839290639163776) -> 0.0078392906 | AR7: =IFERROR(__xludf.DUMMYFUNCTION("IF(NOT(ConfigOn),"""",IFERROR(SPARKLINE(GOOGLEFINANCE(""INDEXBVMF:""&AN7,""price"",TODAY()-$AS$4,TODAY()))))"),"") | AV7: =config.books!$BU$1 -> FALSE
B8: 5.14% | D8: 1.32% | F8: 5.49% | H8: 5.74% | J8: 5.74% | Q8: =DF63 -> 0 | R8: =DG63 -> 0 | S8: =DM63 -> 0 | T8: =DH63 -> 0 | U8: =DF60 -> 0 | V8: =DG60 -> 0 | W8: =DL60 -> 0 | X8: =DK60-Y8 -> 0 | Y8: =DN65 -> 0 | Z8: =DJ60 -> 0 | AA8: =DM60 -> 0 | AB8: =$DF$61 -> 0 | AC8: =$DG$61 -> 0 | AD8: =DL61 -> 0 | AE8: =DK61 -> 0 | AF8: =DJ61 -> 0 | AG8: =$DM$61 -> 0 | AH8: =$DF$62 -> 0 | AI8: =DG62 -> 0 | AJ8: =DM62 -> 0 | AK8: =DN63 -> -0.0014149368 | AL8: =DO63 -> -0.016847727 | AN8: ="USD"&'config.parâmetros'!$B$8 -> USDBRL | AO8: =BT81 -> 5.1928009 | AP8: =IFERROR(__xludf.DUMMYFUNCTION("IF(NOT(ConfigOn),"""",IFERROR(AO8/INDEX(SORT(GOOGLEFINANCE(AN8,""price"",TODAY()-3,TODAY(),1),1,0),2,2)-1))"),0.005596721470206623) -> 0.0055967215 | AQ8: =IFERROR(__xludf.DUMMYFUNCTION("IF(NOT(ConfigOn),"""",IFERROR(AO8/INDEX(GOOGLEFINANCE(AN8,""price"",TODAY()-$AS$4,TODAY(),1),2,2)-1))"),2.3131789814301307E-4) -> 0.0002313179 | AR8: =IFERROR(__xludf.DUMMYFUNCTION("IF(NOT(ConfigOn),"""",IFERROR(SPARKLINE(GOOGLEFINANCE(AN8,""price"",TODAY()-$AS$4,TODAY()))))"),"") | AV8: =AND($M$20,ConfigOn,carteiras.!$AE$4>0) -> FALSE
B10: IBOVESPA | H10: gráfico últimos 10 dias | M10: FALSE | N10: BOOKS | Q10: TOTAL | R10: =IFERROR(__xludf.DUMMYFUNCTION("IF(NOT($AV$7),"""",IFERROR(TRANSPOSE(query({config.books!BN5:BV14;config.books!BN22:BV24},""select Col2 where Col2 is not null and Col4<>0 order by Col9""))))"),"") | AN10: IBOV | AO10: =AO6 -> 183969.34 | AP10: =AP6 -> 0.0028 | AQ10: =AQ6 -> -0.012198217 | AR10: =IFERROR(__xludf.DUMMYFUNCTION("IF(NOT(ConfigOn),"""",IFERROR(SPARKLINE(GOOGLEFINANCE(""INDEXBVMF:""&AN10,""price"",TODAY()-$AS$4,TODAY()))))"),"") | AV10: Multi invest
B11: =IF(NOT(ConfigOn),"",IFERROR(TEXT(IBOVPRICE,"#,##0.00"),"")) -> 183.969,34 | G11: =IF(NOT(ConfigOn),"",TEXT(IBOVCHANGE,"#,##0.00")&" ("&TEXT(IBOVCHANGEPCT,"#,##0.00")&"%)") -> 522,34 (0,28%) | AN11: IFIX | AO11: =AO7 -> 3873.59 | AP11: =AP7 -> -0.0007 | AQ11: =AQ7 -> 0.0078392906 | AR11: =IFERROR(__xludf.DUMMYFUNCTION("IF(NOT(ConfigOn),"""",IFERROR(SPARKLINE(GOOGLEFINANCE(""INDEXBVMF:""&AN11,""price"",TODAY()-$AS$4,TODAY()))))"),"") | AV11: ='config.parâmetros'!P7
B12: =IFERROR(__xludf.DUMMYFUNCTION("IF(NOT(ConfigOn),"""",IFERROR(SPARKLINE(IBOVCHANGEHISTORICO,{""charttype"",""column"";""negcolor"",""red""}),""Dados não disponíveis no momento""))"),"") | M12: PESO DESEJADO % | Q12: =IF(NOT(config.books!$BU$1),"","100%") | R12: =IFERROR(__xludf.DUMMYFUNCTION("IF(NOT($AV$7),"""",IFERROR(TRANSPOSE(query({config.books!BN5:BV14;config.books!BN22:BV24},""select Col3 where Col2 is not null and Col4<>0 order by Col9""))))"),"") | AN12: .DJI | AO12: =IFERROR(__xludf.DUMMYFUNCTION("IF(NOT(ConfigOn),"""",IFERROR(GOOGLEFINANCE(AN12)))"),47417.27) -> 47417.27 | AP12: =IFERROR(__xludf.DUMMYFUNCTION("IF(NOT(ConfigOn),"""",IFERROR(AO12/INDEX(SORT(GOOGLEFINANCE(AN12,""price"",TODAY()-3,TODAY(),1),1,0),2,2)-1))"),-0.006062904203220976) -> -0.0060629042 | AQ12: =IFERROR(__xludf.DUMMYFUNCTION("IF(NOT(ConfigOn),"""",IFERROR(AO12/INDEX(GOOGLEFINANCE(AN12,""price"",TODAY()-$AS$4,TODAY(),1),2,2)-1))"),-0.0542246499362633) -> -0.05422465 | AR12: =IFERROR(__xludf.DUMMYFUNCTION("IF(NOT(ConfigOn),"""",IFERROR(SPARKLINE(GOOGLEFINANCE(AN12,""price"",TODAY()-$AS$4,TODAY()))))"),"")
M13: PESO ATUAL% | R13: =IFERROR(__xludf.DUMMYFUNCTION("IF(NOT($AV$7),"""",IFERROR(TRANSPOSE(query({config.books!BN5:BV14;config.books!BN22:BV24},""select Col6,Col4,Col5 where Col2 is not null and Col4<>0 order by Col9""))))"),"") | AN13: .IXIC | AO13: =IFERROR(__xludf.DUMMYFUNCTION("IF(NOT(ConfigOn),"""",IFERROR(GOOGLEFINANCE(AN13)))"),22716.14) -> 22716.14 | AP13: =IFERROR(__xludf.DUMMYFUNCTION("IF(NOT(ConfigOn),"""",IFERROR(AO13/INDEX(SORT(GOOGLEFINANCE(AN13,""price"",TODAY()-3,TODAY(),1),1,0),2,2)-1))"),0.0) -> 0 | AQ13: =IFERROR(__xludf.DUMMYFUNCTION("IF(NOT(ConfigOn),"""",IFERROR(AO13/INDEX(GOOGLEFINANCE(AN13,""price"",TODAY()-$AS$4,TODAY(),1),2,2)-1))"),-0.022485365986951833) -> -0.022485366 | AR13: =IFERROR(__xludf.DUMMYFUNCTION("IF(NOT(ConfigOn),"""",IFERROR(SPARKLINE(GOOGLEFINANCE(AN13,""price"",TODAY()-$AS$4,TODAY()))))"),"") | AV13: Só ativos com indicação?
B14: IFIX | H14: gráfico últimos 10 dias | M14: FLUXO DE CAIXA | Q14: =IF(NOT(config.books!$BU$1),"",IFERROR(SUM(config.books!BQ22:BQ24),0)) | AN14: ="USD"&'config.parâmetros'!$B$8 -> USDBRL | AO14: =AO8 -> 5.1928009 | AP14: =AP8 -> 0.0055967215 | AQ14: =AQ8 -> 0.0002313179 | AR14: =IFERROR(__xludf.DUMMYFUNCTION("IF(NOT(ConfigOn),"""",IFERROR(SPARKLINE(GOOGLEFINANCE(AN14,""price"",TODAY()-$AS$4,TODAY()))))"),"") | AV14: =IF(AJ42="Ativos com posição",FALSE,TRUE) -> FALSE
B15: =IF(NOT(ConfigOn),"",IFERROR(TEXT(IFIXPRICE,"#,##0.00"),"")) -> 3.873,59 | G15: =IF(NOT(ConfigOn),"",TEXT(IFIXCHANGE,"#,##0.00")&" ("&TEXT(IFIXCHANGEPCT,"0.00")&"%)") -> -2,86 (-0,07%) | M15: VALOR DE MERCADO | Q15: =IF(NOT(config.books!$BU$1),"",IFERROR(SUM(config.books!BR22:BR24),0)) | AN15: BTCUSD | AO15: =IFERROR(__xludf.DUMMYFUNCTION("IF(NOT(ConfigOn),"""",IFERROR(GOOGLEFINANCE(AN15)))"),70264.21) -> 70264.21 | AP15: =IFERROR(__xludf.DUMMYFUNCTION("IF(NOT(ConfigOn),"""",IFERROR(AO15/INDEX(SORT(GOOGLEFINANCE(AN15,""price"",TODAY()-3,TODAY(),1),1,0),2,2)-1))"),0.004717571308724411) -> 0.0047175713 | AQ15: =IFERROR(__xludf.DUMMYFUNCTION("IF(NOT(ConfigOn),"""",IFERROR(AO15/INDEX(GOOGLEFINANCE(AN15,""price"",TODAY()-$AS$4,TODAY(),1),2,2)-1))"),-0.010452577450401956) -> -0.010452577 | AR15: =IFERROR(__xludf.DUMMYFUNCTION("IF(NOT(ConfigOn),"""",IFERROR(SPARKLINE(GOOGLEFINANCE(AN15,""price"",TODAY()-$AS$4,TODAY()))))"),"")
B16: =IFERROR(__xludf.DUMMYFUNCTION("IF(NOT(ConfigOn),"""",IFERROR(SPARKLINE(IFIXCHANGEHISTORICO,{""charttype"",""column"";""negcolor"",""red""}),""Dados não disponíveis no momento""))"),"")
M17: LUCRO TOTAL SOBRE O FLUXO DE CAIXA | Q17: =IF(NOT(config.books!$BU$1),"",SUM(config.books!BT22:BT24)) | R17: =IFERROR(__xludf.DUMMYFUNCTION("IF(NOT($AV$7),"""",IFERROR(TRANSPOSE(query({config.books!BN5:BV14;config.books!BN22:BV24},""select Col7,Col8 where Col2 is not null and Col4<>0 order by Col9""))))"),"") | AN17: =B4 -> SELIC | AO17: =B7 -> LTN-23 | AP17: =D7 -> LTN-26 | AQ17: =F7 -> NTNB-26 | AR17: =H7 -> NTNB-35 | AS17: =J7 -> NTNB-45 | AV17: Total ou sem carteiras?
Q18: =IF(NOT($AV$7),"",IFERROR(Q17/Q15,"")) | AN18: =B5 -> 0.1275 | AO18: =B8 -> 5.14% | AP18: =D8 -> 1.32% | AQ18: =H8 -> 5.74% | AR18: =H8 -> 5.74% | AS18: =J8 -> 5.74% | AV18: =OR(CW63,carteiras.!$AE$4=0,NOT(M20)) -> TRUE
B20: MAIORES LUCROS/PREJUÍZOS HOJE | I20: AÇÃO | M20: TRUE | N20: CARTEIRAS | Q20: TRUE | R20: FALSE | S20: FALSE | T20: FALSE | U20: FALSE | V20: FALSE | W20: FALSE | X20: FALSE | Y20: FALSE | Z20: FALSE | AA20: FALSE | AB20: FALSE | AC20: FALSE | AD20: FALSE | AE20: FALSE | AF20: FALSE | AG20: FALSE | AH20: FALSE | AI20: FALSE | AJ20: FALSE | AK20: FALSE | AL20: FALSE | AN20: FALSE | AP20: CORRETORA | AQ20: TOTAL (A+B) | AR20: BRL (A) | AS20: USD (B)
B21: {=TRANSPOSE(BW44:BW53)} | Q21: =IFERROR(__xludf.DUMMYFUNCTION("TRANSPOSE(IFERROR(query({CZ44:DP53;CZ55:DP58;CZ60:DP63},""select Col1,Col5,Col3,Col4 where Col1<>'' and Col1<>'-' order by Col17"",0)))"),"") | AN21: CONTROLE DO SALDO EM CAIXA
M22: PESO DESEJADO % | AN22: Saldo Inicial (+) | AP22: =IFERROR(__xludf.DUMMYFUNCTION("IF(NOT(caixa!$AC$7),"""",SUM(IFERROR(FILTER(caixa!$O$5:$O$24,caixa!$M$5:$M$24=VLOOKUP($AP$21,caixa!$AB$10:$AD$29,2,FALSE),caixa!$N$5:$N$24=VLOOKUP($AP$21,caixa!$AB$10:$AD$29,3,FALSE)),0)))"),"") | AQ22: =caixa!AE8 | AR22: =caixa!AE5 | AS22: =caixa!AE6
M23: PESO ATUAL % | AN23: Remessas e saques (+) | AP23: =IFERROR(__xludf.DUMMYFUNCTION("IF(NOT(caixa!$AC$7),"""",SUM(IFERROR(FILTER(caixa!$R$5:$R$24,caixa!$M$5:$M$24=VLOOKUP($AP$21,caixa!$AB$10:$AD$29,2,FALSE),caixa!$N$5:$N$24=VLOOKUP($AP$21,caixa!$AB$10:$AD$29,3,FALSE)),0)))"),"") | AQ23: =caixa!AF8 | AR23: =caixa!AF5 | AS23: =caixa!AF6
B24: =IFERROR(__xludf.DUMMYFUNCTION("TRANSPOSE(SPARKLINE({BV44:BV53},{""charttype"",""column"";""negcolor"",""red""}))"),"") | M24: PESO NO SUBGRUPO % | AN24: Outros créditos e débitos (+) | AP24: =IFERROR(__xludf.DUMMYFUNCTION("IF(NOT(caixa!$AC$7),"""",SUM(IFERROR(FILTER(caixa!$S$5:$S$24,caixa!$M$5:$M$24=VLOOKUP($AP$21,caixa!$AB$10:$AD$29,2,FALSE),caixa!$N$5:$N$24=VLOOKUP($AP$21,caixa!$AB$10:$AD$29,3,FALSE)),0)))"),"") | AQ24: =caixa!AG8 | AR24: =caixa!AG5 | AS24: =caixa!AG6
M26: FLUXO DE CAIXA | Q26: =IFERROR(__xludf.DUMMYFUNCTION("TRANSPOSE(IFERROR(query({CZ44:DP53;CZ55:DP58;CZ60:DP63},""select Col6,Col7,Col8 where Col1<>'' and Col1<>'-' order by Col17"",0)))"),"") | AN26: Proventos recebidos (+) | AP26: =IFERROR(__xludf.DUMMYFUNCTION("IF(NOT(caixa!$AC$7),"""",SUM(IFERROR(FILTER(caixa!$U$5:$U$24,caixa!$M$5:$M$24=VLOOKUP($AP$21,caixa!$AB$10:$AD$29,2,FALSE),caixa!$N$5:$N$24=VLOOKUP($AP$21,caixa!$AB$10:$AD$29,3,FALSE)),0)))"),"") | AQ26: =caixa!AI8 | AR26: =caixa!AI5 | AS26: =caixa!AI6
M27: VALOR INVESTIDO | AN27: Day trade (+) | AP27: =IFERROR(__xludf.DUMMYFUNCTION("IF(NOT(caixa!$AC$7),"""",SUM(IFERROR(FILTER(caixa!$T$5:$T$24,caixa!$M$5:$M$24=VLOOKUP($AP$21,caixa!$AB$10:$AD$29,2,FALSE),caixa!$N$5:$N$24=VLOOKUP($AP$21,caixa!$AB$10:$AD$29,3,FALSE)),0)))"),"") | AQ27: =caixa!AH8 | AR27: =caixa!AH5 | AS27: =caixa!AH6
M28: VALOR DE MERCADO | AN28: Operações realizadas (-) | AP28: =IFERROR(__xludf.DUMMYFUNCTION("IF(NOT(caixa!$AC$7),"""",SUM(IFERROR(FILTER(caixa!$V$5:$V$24,caixa!$M$5:$M$24=VLOOKUP($AP$21,caixa!$AB$10:$AD$29,2,FALSE),caixa!$N$5:$N$24=VLOOKUP($AP$21,caixa!$AB$10:$AD$29,3,FALSE)),0)))"),"") | AQ28: =caixa!AJ8 | AR28: =caixa!AJ5 | AS28: =caixa!AJ6
M30: LUCRO DIA | Q30: =IFERROR(__xludf.DUMMYFUNCTION("TRANSPOSE(IFERROR(query({CZ44:DP53;CZ55:DP58;CZ60:DP63},""select Col9,Col10 where Col1<>'' and Col1<>'-' order by Col17"",0)))"),"") | AN30: SALDO EM CAIXA (=) | AP30: =IFERROR(__xludf.DUMMYFUNCTION("IF(NOT(caixa!$AC$7),"""",SUM(IFERROR(FILTER(caixa!$W$5:$W$24,caixa!$M$5:$M$24=VLOOKUP($AP$21,caixa!$AB$10:$AD$29,2,FALSE),caixa!$N$5:$N$24=VLOOKUP($AP$21,caixa!$AB$10:$AD$29,3,FALSE)),0)))"),"") | AQ30: =caixa!AK8 | AR30: =caixa!AK5 | AS30: =caixa!AK6
M33: PROVENTOS | Q33: =IFERROR(__xludf.DUMMYFUNCTION("TRANSPOSE(IFERROR(query({CZ44:DP53;CZ55:DP58;CZ60:DP63},""select Col11,Col12,Col13,Col14 where Col1<>'' and Col1<>'-' order by Col17"",0)))"),"") | AN33: REMESSAS PARA INVESTIMENTO | AR33: CORRETORA | AS33: SALDO | AV33: FILTROS
M34: TRADES | AN34: Média Mensal | AO34: =caixa!Z16 | AP34: Últimos 12 m | AQ34: =caixa!Z24 | AR34: {=caixa!Y30:Z32} | AV34: =IFERROR(__xludf.DUMMYFUNCTION("IFERROR("" and (""&AZ42&""='""&join(""' or ""&AZ42&""='"",QUERY({BH44:BH343},""select Col1 where Col1 is not null""))&""') "")"),"")
M35: LUCRO ABERTO | AN35: {=caixa!Y18:Z19} -> 46112 | AP35: {=caixa!Y25:Z26} -> 2026 | AV35: =IFERROR(__xludf.DUMMYFUNCTION("IFERROR("" and (""&$BA$42&"" like '""&join(""' or ""&$BA$42&"" like '"",Filter($AI$44:$AI$62,($AJ$44:$AJ$62=TRUE)*($AI$44:$AI$62<>"""")))&""') "","" and ""&$BA$42&""='***###@@@'"")")," and Col4='***###@@@'") -> and Col4='***###@@@'
B36: {=TRANSPOSE(BS44:BS53)} | M36: LUCRO TOTAL | AN36: 46081 | AP36: 2025 | AV36: =IFERROR(__xludf.DUMMYFUNCTION("IFERROR("" and (""&$BF$42&"" like '""&join(""' or ""&$BF$42&"" like '"",Filter($AK$44:$AK$62,($AL$44:$AL$62=TRUE)*($AK$44:$AK$62<>"""")))&""') "",$BF$42&""='***###@@@'"")"),"Col20='***###@@@'") -> Col20='***###@@@'
M37: =("Col"&MATCH(M$40,portfolio.!$A$3:DQ$3,0)) -> Col68 | N37: =("Col"&MATCH(N$40,portfolio.!$A$3:$BO$3,0)) -> Col54 | P37: =("Col"&MATCH(P$40,portfolio.!$A$3:$BO$3,0)) -> Col56 | Q37: =("Col"&MATCH(Q$40,portfolio.!$A$3:$BO$3,0)) -> Col64 | R37: =("Col"&MATCH(R$40,portfolio.!$A$3:$BO$3,0)) -> Col39 | S37: =("Col"&MATCH(S$40,portfolio.!$A$3:$BO$3,0)) -> Col58 | T37: =("Col"&MATCH(T$40,portfolio.!$A$3:$BO$3,0)) -> Col15 | U37: =("Col"&MATCH(U$40,portfolio.!$A$3:$BO$3,0)) -> Col40 | V37: =("Col"&MATCH(V$40,portfolio.!$A$3:$BO$3,0)) -> Col60 | X37: =("Col"&MATCH(X$40,portfolio.!$A$3:$BO$3,0)) -> Col43 | Y37: =("Col"&MATCH(Y$40,portfolio.!$A$3:$BO$3,0)) -> Col44 | Z37: =("Col"&MATCH(Z$40,portfolio.!$A$3:$BO$3,0)) -> Col61 | AA37: =("Col"&MATCH(AA$40,portfolio.!$A$3:$BO$3,0)) -> Col63 | AB37: =("Col"&MATCH(AB$40,portfolio.!$A$3:$BO$3,0)) -> Col67 | AC37: =("Col"&MATCH(AC$40,portfolio.!$A$3:$BO$3,0)) -> Col66 | AD37: =("Col"&MATCH(AD$40,portfolio.!$A$3:$BO$3,0)) -> Col7 | AF37: =("Col"&MATCH(AF$40,portfolio.!$A$3:$BO$3,0)) -> Col45 | AN37: {=caixa!Y20:Z20} -> 46053 | AP37: {=caixa!Y27:Z27} -> 2024 | AR37: {=caixa!Y33:Z34}
M38: RENTABILIDADE (TIR) | Q38: =IFERROR(__xludf.DUMMYFUNCTION("TRANSPOSE(IFERROR(query({CZ44:DP53;CZ55:DP58;CZ60:DP63},""select Col15, Col16 where Col1<>'' and Col1<>'-' order by Col17"",0)))"),"")
AN39: {=caixa!Y21:Z21} -> 46022 | AP39: {=caixa!Y28:Z28} -> 2023 | AR39: {=caixa!Y34:Z34} | AV39: ORDENAMENTO | AZ39: FORMATACAO CONDICIONAL | BH39: FILTRO DOS ATIVOS | BP39: GRÁFICO DE MAIORES LUCROS E PREJUÍZOS DO DIA | BY39: DADOS PARA GERAÇÃO DOS GRÁFICOS | CM39: GRAFICO EXPOSIÇÃO | CO39: GRÁFICO LUCROS | CR39: SELEÇÃO DO GRÁFICO A SER EXIBIDO | CV39: CÁLCULOS DO PAINEL
M40: nome_pregao_portfolio | N40: ocorrencias | P40: qtd_atual+corretora | Q40: =if(Q41="PM","pm_atual","pm_ajust") -> pm_ajust | R40: cotacao | S40: pr_teto+upside | T40: vlr_investido | U40: vlr_mercado | V40: lucro_dia+pct | X40: lucro_aberto | Y40: lucro_aberto_pct | Z40: trades+pct | AA40: provento+pct | AB40: lucro_total | AC40: tir_am+aa | AD40: =IF(AD41="Setor","setor","subsetor") -> setor | AF40: dias_pct
B41: CARTEIRAS ONDE HÁ EXPOSIÇÃO | M41: ▼ | N41: Em x cart. | O41: Peso % | P41: Custódia | Q41: PM (PM Ajust) | R41: Cotação | S41: Preço Teto | T41: Valor Investido | U41: Valor de Mercado | V41: Lucro Dia | X41: =IFERROR(__xludf.DUMMYFUNCTION("""Lucros | Média Mensal Proventos: ""&IF(ConfigOn,TEXT(IFERROR(query({AtivosDados},""select sum(""&BH42&"") where Col1 is not null ""&AV34&AV35&AV36&"" label sum(""&BH42&"") ''""),0),""#,###,##0.00""),"""")"),"Lucros | Média Mensal Proventos: 0,00") -> Lucros | Média Mensal Proventos: 0,00 | AC41: TIR | AD41: Setor | AF41: Desempenho | AI41: OPÇÕES DE FILTROS | AN41: EXPOSIÇÃO POR SETOR | AV41: lucro_dia | AW41: provento | AX41: trades | AZ41: ativo | BA41: classe | BB41: tir_am | BC41: trades | BD41: lucro_dia_pct | BE41: upside | BF41: corretora_investidor | BH41: provento_avg | BP41: MAX (+) | BQ41: =IF(ConfigOn,COUNTIFS(portfolio.!$D$4:$D343,$BT$41,portfolio.!$AO$4:$AO343,">=0"),0) -> 0 | BR41: =IF(NOT(ConfigOn),"",IF(BQ41+BQ42<10,BQ41,IF(BQ42<5,10-BQ42,IF(BQ41<5,BQ41,5)))) -> 0 | BS41: CLASSE -> | BT41: =I20 -> AÇÃO | BY41: PERFIL | BZ41: VALOR MERCADO POR PERFIL | CA41: LUCRO POR PERFIL | CB41: NOME DAS CARTEIRAS | CC41: VALOR MERCADO POR CARTEIRA | CD41: LUCRO POR CARTEIRA | CE41: NOME DOS BOOKS | CF41: VALOR MERCADO POR BOOK | CG41: LUCRO POR BOOK | CH41: ATIVO | CI41: SETOR | CJ41: CLASSE | CK41: VLR DE MERCADO POR ATIVO | CL41: LUCRO POR ATIVO | CM41: LEGENDA | CN41: VALOR | CO41: LEGENDA | CP41: VALOR | CR41: LISTA GRÁFICOS 1 | CS41: QUERY
M42: LUCRO DIA % | V42: ='config.parâmetros'!B8 -> BRL | W42: % | X42: Aberto | Y42: % | Z42: Trades | AA42: Proventos | AB42: Total | AC42: ="% am"&" % aa" -> % am % aa | AF42: =AF43&" dias (%)" -> 30 dias (%) | AG42: ="Gráfico "&AF43&" dias" -> Gráfico 30 dias | AI42: Exibir ▶ | AJ42: Ativos com posição | AV42: ="Col"&MATCH(AV41,portfolio.!$A$3:$BO$3,0) -> Col41 | AW42: ="Col"&MATCH(AW41,portfolio.!$A$3:$BO$3,0) -> Col50 | AX42: ="Col"&MATCH(AX41,portfolio.!$A$3:$BO$3,0) -> Col52 | AZ42: ="Col"&MATCH(AZ41,portfolio.!$A$3:$BO$3,0) -> Col1 | BA42: ="Col"&MATCH(BA41,portfolio.!$A$3:$BO$3,0) -> Col4 | BB42: ="Col"&MATCH(BB41,portfolio.!$A$3:$BO$3,0) -> Col65 | BC42: ="Col"&MATCH(BC41,portfolio.!$A$3:$BO$3,0) -> Col52 | BD42: ="Col"&MATCH(BD41,portfolio.!$A$3:$BO$3,0) -> Col42 | BE42: ="Col"&MATCH(BE41,portfolio.!$A$3:$BO$3,0) -> Col57 | BF42: ="Col"&MATCH(BF41,portfolio.!$A$3:$BO$3,0) -> Col20 | BH42: ="Col"&MATCH(BH41,portfolio.!$A$3:$BO$3,0) -> Col51 | BP42: MAX( -) | BQ42: =IF(ConfigOn,COUNTIFS(portfolio.!$D$4:$D343,$BT$41,portfolio.!$AO$4:$AO343,"<0"),0) -> 0 | BR42: =IF(NOT(ConfigOn),"",IF(BQ42+BQ41<10,BQ42,IF(BQ41<5,10-BQ41,IF(BQ42<5,BQ42,5)))) -> 0 | BS42: ATIVOS 5+ e 5- NOBLANK | BT42: LUCRO DIA 5+ NOBLANK | BU42: LUCRO DIA 5- NOBLANK | BV42: LUCRO DIA 10 AÇÕES | BW42: LUCRO DIA 10 AÇÕES | CR42: EXPOSIÇÃO POR ATIVO | CS42: ="select Col10, Col13 where Col10 is not null" -> select Col10, Col13 where Col10 is not null | CZ42: 1 | DA42: 2 | DB42: 3 | DC42: 4 | DD42: 5 | DE42: 6 | DF42: 7 | DG42: 8 | DH42: 9 | DI42: 10 | DJ42: 11 | DK42: 12 | DL42: 13 | DM42: 14 | DN42: 15 | DO42: 16 | DP42: 17
B43: {=IF(AV8,TRANSPOSE(CarteirasListaCriadasAbreviada),"")} | M43: ATIVOS | O43: =IF(ConfigOn,SUM(O44:O343),"") -> 0 | P43: CUSTÓDIA E VALOR DOS ATIVOS POR UNIDADE | T43: =IF(ConfigOn,SUM(T44:T343),"") -> 0 | U43: =IF(ConfigOn,SUM(U44:U343),"") -> 0 | V43: =IFERROR(__xludf.DUMMYFUNCTION("IF(ConfigOn,IFERROR(query({AtivosDados},""select sum(""&AV42&"") where Col1 is not null ""&AV34&AV35&AV36&"" label sum(""&AV42&"") ''""),0),"""")"),0.0) -> 0 | W43: =IF(ConfigOn,IFERROR(V43/T43,0),"") -> 0 | X43: =IF(ConfigOn,SUM(X44:X343),"") -> 0 | Y43: =IF(ConfigOn,IFERROR(X43/U43,0),"") -> 0 | Z43: =IFERROR(__xludf.DUMMYFUNCTION("IF(ConfigOn,IFERROR(query({AtivosDados},""select sum(""&AX42&"") where Col1 is not null ""&AV34&AV35&AV36&"" label sum(""&AX42&"") ''""),0),"""")"),0.0) -> 0 | AA43: =IFERROR(__xludf.DUMMYFUNCTION("IF(ConfigOn,IFERROR(query({AtivosDados},""select sum(""&AW42&"") where Col1 is not null ""&AV34&AV35&AV36&"" label sum(""&AW42&"") ''""),0),"""")"),0.0) -> 0 | AB43: =IF(ConfigOn,AA43+Z43+X43,"") -> 0 | AF43: 30 | AG43: Gráfico de linha | AI43: filtrar por classe | AK43: filtrar por corretora | AV43: ORDEM | AW43: NOME DA COLUNA | AX43: COLUNA | AZ43: ATIVOS ORDENADOS | BA43: CLASSE ORDENADOS | BB43: TIR MENSAL | BD43: LUCRO DIA | BE43: PRECO TETO UPSIZE | BF43: LUCRO DIA ABS | BH43: SELECTED | BI43: SUBTOTAL 01 | BJ43: GRUPO 01 | BK43: SUBTOTAL 02 | BL43: GRUPO 02 | BM43: SUBTOTAL 03 | BP43: ATIVOS 5+ e 5- | BQ43: LUCRO DIA 5+ | BR43: LUCRO DIA 5- | BY43: 1 | BZ43: 2 | CA43: 3 | CB43: 4 | CC43: 5 | CD43: 6 | CE43: 7 | CF43: 8 | CG43: 9 | CH43: 10 | CI43: 11 | CJ43: 12 | CK43: 13 | CL43: 14 | CM43: =AN41 -> EXPOSIÇÃO POR SETOR | CO43: =AN50 -> LUCRO POR SETOR | CR43: ="EXPOSIÇÃO POR "&UPPER(AD41) -> EXPOSIÇÃO POR SETOR | CS43: select Col11, sum(Col13) where Col11 is not null group by Col11 label sum(Col13) '' | CV43: GRUPO | CW43: CHECK | CX43: CATEGORIA SUBTOTAL | CY43: PERFIL CRIADAS | CZ43: CARTEIRAS CRIADAS | DB43: PESO % | DC43: PESO GRUPO % | DD43: PESO DESEJADO % | DE43: Valor Aportado | DF43: Valor Investido | DG43: Valor Mercado | DH43: Lucro dia R$ | DI43: Lucro dia % | DJ43: Valor Proventos | DK43: Valor Trades | DL43: Lucro Aberto | DM43: Lucro Total | DN43: TIR am | DO43: TIR aa | DP43: ORDER
B44: =IFERROR(__xludf.DUMMYFUNCTION("IF(B$43="""","""",IF($AZ44="""","""",IFERROR(Query({CarteirasAtivos},""Select Col3 where Col1 = '""&$AZ44&""'and Col2 = '""&S$21&""'""))))"),"") | C44: =IFERROR(__xludf.DUMMYFUNCTION("IF(C$43="""","""",IF($AZ44="""","""",IFERROR(Query({CarteirasAtivos},""Select Col3 where Col1 = '""&$AZ44&""'and Col2 = '""&T$21&""'""))))"),"") | D44: =IFERROR(__xludf.DUMMYFUNCTION("IF(D$43="""","""",IF($AZ44="""","""",IFERROR(Query({CarteirasAtivos},""Select Col3 where Col1 = '""&$AZ44&""'and Col2 = '""&U$21&""'""))))"),"") | E44: =IFERROR(__xludf.DUMMYFUNCTION("IF(E$43="""","""",IF($AZ44="""","""",IFERROR(Query({CarteirasAtivos},""Select Col3 where Col1 = '""&$AZ44&""'and Col2 = '""&V$21&""'""))))"),"") | F44: =IFERROR(__xludf.DUMMYFUNCTION("IF(F$43="""","""",IF($AZ44="""","""",IFERROR(Query({CarteirasAtivos},""Select Col3 where Col1 = '""&$AZ44&""'and Col2 = '""&W$21&""'""))))"),"") | G44: =IFERROR(__xludf.DUMMYFUNCTION("IF(G$43="""","""",IF($AZ44="""","""",IFERROR(Query({CarteirasAtivos},""Select Col3 where Col1 = '""&$AZ44&""'and Col2 = '""&X$21&""'""))))"),"") | H44: =IFERROR(__xludf.DUMMYFUNCTION("IF(H$43="""","""",IF($AZ44="""","""",IFERROR(Query({CarteirasAtivos},""Select Col3 where Col1 = '""&$AZ44&""'and Col2 = '""&Y$21&""'""))))"),"") | I44: =IFERROR(__xludf.DUMMYFUNCTION("IF(I$43="""","""",IF($AZ44="""","""",IFERROR(Query({CarteirasAtivos},""Select Col3 where Col1 = '""&$AZ44&""'and Col2 = '""&Z$21&""'""))))"),"") | J44: =IFERROR(__xludf.DUMMYFUNCTION("IF(J$43="""","""",IF($AZ44="""","""",IFERROR(Query({CarteirasAtivos},""Select Col3 where Col1 = '""&$AZ44&""'and Col2 = '""&AA$21&""'""))))"),"") | K44: =IFERROR(__xludf.DUMMYFUNCTION("IF(K$43="""","""",IF($AZ44="""","""",IFERROR(Query({CarteirasAtivos},""Select Col3 where Col1 = '""&$AZ44&""'and Col2 = '""&AB$21&""'""))))"),"") | L44: 1 | M44: =IFERROR(__xludf.DUMMYFUNCTION("IF(NOT(ConfigOn),"""",IFERROR(query({AtivosDados},""select ""&join("","",$M$37:$N$37)&"" where Col1 is not null ""&AV34&AV35&AV36&IFERROR(VLOOKUP($M$42,'portfólio'!AV44:AX56,3, FALSE)))))"),"") | O44: {=IF(M44:M343="","",IFERROR(U44:U343/SUM($U44:$U343),""))} | P44: =IFERROR(__xludf.DUMMYFUNCTION("IF(NOT(ConfigOn),"""",IFERROR(query({AtivosDados},""select ""&join("","",$P$37:$V$37)&"" where Col1 is not null ""&AV34&AV35&AV36&IFERROR(VLOOKUP($M$42,'portfólio'!AV44:AX56,3, FALSE)))))"),"") | W44: =IFERROR(__xludf.DUMMYFUNCTION("IF(M44="""","""",sparkline(IFERROR(BF44*100/MAX($BF$44:$BF343),0),{""charttype"",""bar"";""max"",100;""color1"",IF(BD44>=0,""#4760a5"",""red"")}))"),"") | X44: =IFERROR(__xludf.DUMMYFUNCTION("IF(NOT(ConfigOn),"""",IFERROR(query({AtivosDados},""select ""&join("","",$X$37:$AD$37)&"" where Col1 is not null ""&AV34&AV35&AV36&IFERROR(VLOOKUP($M$42,'portfólio'!AV44:AX56,3, FALSE)))))"),"") | AF44: =IFERROR(__xludf.DUMMYFUNCTION("IF(NOT(ConfigOn),"""",IFERROR(query({AtivosDados},""select ""&join("","",$AF$37)&"" where Col1 is not null ""&AV34&AV35&AV36&IFERROR(VLOOKUP($M$42,'portfólio'!AV44:AX56,3, FALSE)))))"),"") | AG44: =IFERROR(__xludf.DUMMYFUNCTION("IF($M44="""","""",IFERROR(sparkline(query(GOOGLEFINANCE($AZ44,""price"",TODAY()-$AF$43,TODAY(),1),""select Col2 label Col2 ''""),IF($AG$43=""Gráfico de barras"",{""charttype"",""column"";""highcolor"",""red""},{""chartype"",""line""}))))"),"") | AI44: {=SORT(UNIQUE(portfolio.!D4:D343))} | AJ44: TRUE | AK44: {=SORT(UNIQUE(portfolio.!T4:T343))} | AL44: TRUE | AU44: 1 | AV44: RANKING | AW44: ranking | AX44: ="order by Col"&MATCH(AW44,portfolio.!$A$3:$BO$3,0)&" "&IFERROR(VLOOKUP($M$41,$AV$57:$AX$58,3, FALSE),"") -> order by Col53 asc | AY44: 1 | AZ44: =IFERROR(__xludf.DUMMYFUNCTION("IFERROR(query({AtivosDados},""select ""&JOIN("","",$AZ$42:$BE$42)&"" where Col1 is not null ""&AV34&AV35&AV36&IFERROR(VLOOKUP($M$42,'portfólio'!AV44:AX56,3, FALSE))))"),"") | BF44: {=IF(AZ44:AZ343="","",abs(BD44:BD343))} | BG44: 1 | BH44: =IFERROR(__xludf.DUMMYFUNCTION("IF($AV$18,{AtivosLista},UNIQUE(IFERROR(QUERY({BI44:BI343;BJ44:BJ343;BK44:BK343;BL44:BL343;BM44:BM343},""select Col1 where Col1 is not null limit 300""))))"),"") | BI44: =IFERROR(__xludf.DUMMYFUNCTION("IF(AV18,"""",IF(CW60,IFERROR(FILTER(portfolio.!A4:A303,portfolio.!U4:U303=CX60)),""""))"),"") | BJ44: =IFERROR(__xludf.DUMMYFUNCTION("IF(AV18,"""",IF(NOT(CW60),unique(IFERROR(query(IF($AV$14,{CarteirasAtivos},{CarteirasAtivos;CarteirasAtivosEncerrados}),""Select Col1 where Col1 is not null and (Col2 = '""&join(""' or Col2 = '"",filter(CZ44:CZ53,CW44:CW53))&""') order by Col3 limit 300"""&"))),""""))"),"") | BK44: =IFERROR(__xludf.DUMMYFUNCTION("IF(AV18,"""",IF(CW61,IFERROR(FILTER(portfolio.!A4:A303,(portfolio.!U4:U303=CX55)+(portfolio.!U4:U303=CX56)+(portfolio.!U4:U303=CX57)+(portfolio.!U4:U303=CX58))),""""))"),"") | BL44: =IFERROR(__xludf.DUMMYFUNCTION("IF(AV18,"""",IF(NOT(CW61),IFERROR(query({IF(CW55,IFERROR(filter(portfolio.!A4:A303,portfolio.!U4:U303=CX55)),{""""});IF(CW56,IFERROR(filter(portfolio.!A4:A303,portfolio.!U4:U303=CX56)),{""""});IF(CW57,IFERROR(filter(portfolio.!A4:A303,portfolio.!U4:U303=C"&"X57)),{""""});IF(CW58,IFERROR(filter(portfolio.!A4:A303,portfolio.!U4:U303=CX58)),{""""})},""select Col1 where Col1 is not null"")),""""))"),"") | BM44: =IFERROR(__xludf.DUMMYFUNCTION("IF(AV18,"""",IF(CW62,IFERROR(FILTER(portfolio.!A4:A303,portfolio.!U4:U303=CX62)),""""))"),"") | BO44: 1 | BP44: =IFERROR(__xludf.DUMMYFUNCTION("IF(NOT(ConfigOn),query({BP65:BQ74},""select Col1, Col2 where Col2 >= 0 ORDER BY Col2 DESC"",0),IFERROR(query({AtivosDados},""select Col""&MATCH(""ativo"",portfolio.!$A$3:DQ$3,0)&"",Col""&MATCH(""lucro_dia"",portfolio.!$A$3:DQ$3,0)&"" where Col""&MATCH(""c"&"lasse"",portfolio.!$A$3:DQ$3,0)&""='""&$BT$41&""' and Col""&MATCH(""lucro_dia"",portfolio.!$A$3:DQ$3,0)&"">=0 ORDER BY Col""&MATCH(""lucro_dia"",portfolio.!$A$3:DQ$3,0)&"" DESC LIMIT ""&BR41)))"),"") | BS44: =IFERROR(__xludf.DUMMYFUNCTION("IFERROR(query({IFERROR(query({BP44:BR53},""select Col1, Col2, Col3 where Col1 is not null""),{"""","""",""""});IFERROR(query({BP54:BR63},""select Col1, Col2, Col3 where Col1 is not null""),{"""","""",""""})},""select Col1,Col2,Col3 where Col1 is not null"&"""))"),"") | BV44: =IF(AND(BT44="",BU44=""),0,IF(BT44="",BU44,BT44)) -> 0 | BW44: =IF(BV44=0,"",BV44) | BX44: 1 | BY44: {=sort(unique({CY44:CY53;CY55:CY58}))} | BZ44: {=IF(AV8="","",IF(BY44:BY58="",0,SUMIF(CY44:CY58,CONCAT("=",BY44:BY58),DG44:DG58)))} -> 0 | CA44: {=IF(AV8="","",IF(BY44:BY58="",0,SUMIF(CY44:CY58,CONCAT("=",BY44:BY58),DM44:DM58)))} -> 0 | CB44: {={CZ44:CZ53;CZ55:CZ58}} | CC44: {={DG44:DG53;DG55:DG58}} | CD44: {={DM44:DM53;DM55:DM58}} | CE44: {=config.books!BN28:BP38} | CH44: {=AZ44:AZ343} | CI44: {=AD44:AD343} | CJ44: {=BA44:BA343} | CK44: {=U44:U343} | CL44: {=IF(CH44:CH343="","",VLOOKUP(CH44:CH343,AtivosDados,MATCH("lucro_total",portfolio.!$A$3:DQ$3,0),FALSE))} | CM44: =IFERROR(__xludf.DUMMYFUNCTION("IFERROR(query({BY44:CL343},VLOOKUP(CM43,CR42:CS54,2,0)))"),"") | CO44: =IFERROR(__xludf.DUMMYFUNCTION("IFERROR(query({BY44:CL343},VLOOKUP(CO43,CR42:CS54,2,0)))"),"") | CR44: EXPOSIÇÃO POR CLASSE | CS44: select Col12, sum(Col13) where Col11 is not null group by Col12 label sum(Col13) '' | CU44: 1 | CV44: CARTEIRAS | CW44: =IFERROR(__xludf.DUMMYFUNCTION("IFERROR(query({$Q$20:$AL$20},""select Col""&MATCH(CZ44,$Q$21:$AL$21,0)))"),"") | CY44: {=if(AV8,CarteirasListaCriadasPerfis,"")} | CZ44: {=IF(AV8,CarteirasListaCriadas,"")} | DB44: =IFERROR(DG44/$DG$63,"") | DC44: =IFERROR(DB44/SUM($DB$44:$DB$53),"") | DD44: {=IF(NOT($AV$8),"",IF(CZ44="","",VLOOKUP(CZ44,config.carteiras!$C$9:$D$23,2,FALSE)))} | DE44: =IF($CZ44="","",DF44-DK44-DJ44) | DF44: {=IF($CZ44="","",VLOOKUP($CZ44,carteiras..!$B$2:$I$16,2,FALSE))} | DG44: {=IF($CZ44="","",VLOOKUP($CZ44,carteiras..!$B$2:$I$16,3,FALSE))} | DH44: {=IF($CZ44="","",VLOOKUP($CZ44,carteiras..!$B$2:$I$16,4,FALSE))} | DI44: =IF($CZ44="","",IFERROR(DH44/DF44,0)) | DJ44: {=IF($CZ44="","",VLOOKUP($CZ44,carteiras..!$B$2:$I$16,5,FALSE))} | DK44: {=IF($CZ44="","",VLOOKUP($CZ44,carteiras..!$B$2:$I$16,6,FALSE))} | DL44: =IF(ConfigOn,DG44-DF44,0) -> 0 | DM44: =IF($CZ44="","",SUM(DJ44:DL44)) | DN44: {=IF($CZ44="","",VLOOKUP($CZ44,carteiras..!$B$2:$I$16,7,FALSE))} | DO44: {=IF($CZ44="","",VLOOKUP($CZ44,carteiras..!$B$2:$I$16,8,FALSE))} | DP44: 2
B45: =IFERROR(__xludf.DUMMYFUNCTION("IF(B$43="""","""",IF($AZ45="""","""",IFERROR(Query({CarteirasAtivos},""Select Col3 where Col1 = '""&$AZ45&""'and Col2 = '""&S$21&""'""))))"),"") | C45: =IFERROR(__xludf.DUMMYFUNCTION("IF(C$43="""","""",IF($AZ45="""","""",IFERROR(Query({CarteirasAtivos},""Select Col3 where Col1 = '""&$AZ45&""'and Col2 = '""&T$21&""'""))))"),"") | D45: =IFERROR(__xludf.DUMMYFUNCTION("IF(D$43="""","""",IF($AZ45="""","""",IFERROR(Query({CarteirasAtivos},""Select Col3 where Col1 = '""&$AZ45&""'and Col2 = '""&U$21&""'""))))"),"") | E45: =IFERROR(__xludf.DUMMYFUNCTION("IF(E$43="""","""",IF($AZ45="""","""",IFERROR(Query({CarteirasAtivos},""Select Col3 where Col1 = '""&$AZ45&""'and Col2 = '""&V$21&""'""))))"),"") | F45: =IFERROR(__xludf.DUMMYFUNCTION("IF(F$43="""","""",IF($AZ45="""","""",IFERROR(Query({CarteirasAtivos},""Select Col3 where Col1 = '""&$AZ45&""'and Col2 = '""&W$21&""'""))))"),"") | G45: =IFERROR(__xludf.DUMMYFUNCTION("IF(G$43="""","""",IF($AZ45="""","""",IFERROR(Query({CarteirasAtivos},""Select Col3 where Col1 = '""&$AZ45&""'and Col2 = '""&X$21&""'""))))"),"") | H45: =IFERROR(__xludf.DUMMYFUNCTION("IF(H$43="""","""",IF($AZ45="""","""",IFERROR(Query({CarteirasAtivos},""Select Col3 where Col1 = '""&$AZ45&""'and Col2 = '""&Y$21&""'""))))"),"") | I45: =IFERROR(__xludf.DUMMYFUNCTION("IF(I$43="""","""",IF($AZ45="""","""",IFERROR(Query({CarteirasAtivos},""Select Col3 where Col1 = '""&$AZ45&""'and Col2 = '""&Z$21&""'""))))"),"") | J45: =IFERROR(__xludf.DUMMYFUNCTION("IF(J$43="""","""",IF($AZ45="""","""",IFERROR(Query({CarteirasAtivos},""Select Col3 where Col1 = '""&$AZ45&""'and Col2 = '""&AA$21&""'""))))"),"") | K45: =IFERROR(__xludf.DUMMYFUNCTION("IF(K$43="""","""",IF($AZ45="""","""",IFERROR(Query({CarteirasAtivos},""Select Col3 where Col1 = '""&$AZ45&""'and Col2 = '""&AB$21&""'""))))"),"") | L45: 2 | W45: =IFERROR(__xludf.DUMMYFUNCTION("IF(M45="""","""",sparkline(IFERROR(BF45*100/MAX($BF$44:$BF$153),0),{""charttype"",""bar"";""max"",100;""color1"",IF(BD45>=0,""#4760a5"",""red"")}))"),"") | AG45: =IFERROR(__xludf.DUMMYFUNCTION("IF($M45="""","""",IFERROR(sparkline(query(GOOGLEFINANCE($AZ45,""price"",TODAY()-$AF$43,TODAY(),1),""select Col2 label Col2 ''""),IF($AG$43=""Gráfico de barras"",{""charttype"",""column"";""highcolor"",""red""},{""chartype"",""line""}))))"),"") | AJ45: TRUE | AL45: TRUE | AU45: 2 | AV45: LUCRO DIA | AW45: lucro_dia | AX45: ="order by Col"&MATCH(AW45,portfolio.!$A$3:$BO$3,0)&" "&IFERROR(VLOOKUP($M$41,$AV$57:$AX$58,3, FALSE),"") -> order by Col41 asc | AY45: 2 | BG45: 2 | BO45: 2 | BV45: =IF(AND(BT45="",BU45=""),0,IF(BT45="",BU45,BT45)) -> 0 | BW45: =IF(BV45=0,"",BV45) | BX45: 2 | BY45: Outros | BZ45: 0 | CA45: 0 | CR45: =if(AV7,"EXPOSIÇÃO POR BOOK","") | CS45: select Col7, Col8 where Col8>0 | CU45: 2 | CV45: CARTEIRAS | CW45: =IFERROR(__xludf.DUMMYFUNCTION("IFERROR(query({$Q$20:$AL$20},""select Col""&MATCH(CZ45,$Q$21:$AL$21,0)))"),"") | DB45: =IFERROR(DG45/$DG$63,"") | DC45: =IFERROR(DB45/SUM($DB$44:$DB$53),"") | DD45: {=IF(NOT($AV$8),"",IF(CZ45="","",VLOOKUP(CZ45,config.carteiras!$C$9:$D$23,2,FALSE)))} | DE45: =IF($CZ45="","",DF45-DK45-DJ45) | DF45: {=IF($CZ45="","",VLOOKUP($CZ45,carteiras..!$B$2:$I$16,2,FALSE))} | DG45: {=IF($CZ45="","",VLOOKUP($CZ45,carteiras..!$B$2:$I$16,3,FALSE))} | DH45: {=IF($CZ45="","",VLOOKUP($CZ45,carteiras..!$B$2:$I$16,4,FALSE))} | DI45: =IF($CZ45="","",IFERROR(DH45/DF45,0)) | DJ45: {=IF($CZ45="","",VLOOKUP($CZ45,carteiras..!$B$2:$I$16,5,FALSE))} | DK45: {=IF($CZ45="","",VLOOKUP($CZ45,carteiras..!$B$2:$I$16,6,FALSE))} | DL45: =IF(ConfigOn,DG45-DF45,0) -> 0 | DM45: =IF($CZ45="","",SUM(DJ45:DL45)) | DN45: {=IF($CZ45="","",VLOOKUP($CZ45,carteiras..!$B$2:$I$16,7,FALSE))} | DO45: {=IF($CZ45="","",VLOOKUP($CZ45,carteiras..!$B$2:$I$16,8,FALSE))} | DP45: 2
B46: =IFERROR(__xludf.DUMMYFUNCTION("IF(B$43="""","""",IF($AZ46="""","""",IFERROR(Query({CarteirasAtivos},""Select Col3 where Col1 = '""&$AZ46&""'and Col2 = '""&S$21&""'""))))"),"") | C46: =IFERROR(__xludf.DUMMYFUNCTION("IF(C$43="""","""",IF($AZ46="""","""",IFERROR(Query({CarteirasAtivos},""Select Col3 where Col1 = '""&$AZ46&""'and Col2 = '""&T$21&""'""))))"),"") | D46: =IFERROR(__xludf.DUMMYFUNCTION("IF(D$43="""","""",IF($AZ46="""","""",IFERROR(Query({CarteirasAtivos},""Select Col3 where Col1 = '""&$AZ46&""'and Col2 = '""&U$21&""'""))))"),"") | E46: =IFERROR(__xludf.DUMMYFUNCTION("IF(E$43="""","""",IF($AZ46="""","""",IFERROR(Query({CarteirasAtivos},""Select Col3 where Col1 = '""&$AZ46&""'and Col2 = '""&V$21&""'""))))"),"") | F46: =IFERROR(__xludf.DUMMYFUNCTION("IF(F$43="""","""",IF($AZ46="""","""",IFERROR(Query({CarteirasAtivos},""Select Col3 where Col1 = '""&$AZ46&""'and Col2 = '""&W$21&""'""))))"),"") | G46: =IFERROR(__xludf.DUMMYFUNCTION("IF(G$43="""","""",IF($AZ46="""","""",IFERROR(Query({CarteirasAtivos},""Select Col3 where Col1 = '""&$AZ46&""'and Col2 = '""&X$21&""'""))))"),"") | H46: =IFERROR(__xludf.DUMMYFUNCTION("IF(H$43="""","""",IF($AZ46="""","""",IFERROR(Query({CarteirasAtivos},""Select Col3 where Col1 = '""&$AZ46&""'and Col2 = '""&Y$21&""'""))))"),"") | I46: =IFERROR(__xludf.DUMMYFUNCTION("IF(I$43="""","""",IF($AZ46="""","""",IFERROR(Query({CarteirasAtivos},""Select Col3 where Col1 = '""&$AZ46&""'and Col2 = '""&Z$21&""'""))))"),"") | J46: =IFERROR(__xludf.DUMMYFUNCTION("IF(J$43="""","""",IF($AZ46="""","""",IFERROR(Query({CarteirasAtivos},""Select Col3 where Col1 = '""&$AZ46&""'and Col2 = '""&AA$21&""'""))))"),"") | K46: =IFERROR(__xludf.DUMMYFUNCTION("IF(K$43="""","""",IF($AZ46="""","""",IFERROR(Query({CarteirasAtivos},""Select Col3 where Col1 = '""&$AZ46&""'and Col2 = '""&AB$21&""'""))))"),"") | L46: 3 | W46: =IFERROR(__xludf.DUMMYFUNCTION("IF(M46="""","""",sparkline(IFERROR(BF46*100/MAX($BF$44:$BF$153),0),{""charttype"",""bar"";""max"",100;""color1"",IF(BD46>=0,""#4760a5"",""red"")}))"),"") | AG46: =IFERROR(__xludf.DUMMYFUNCTION("IF($M46="""","""",IFERROR(sparkline(query(GOOGLEFINANCE($AZ46,""price"",TODAY()-$AF$43,TODAY(),1),""select Col2 label Col2 ''""),IF($AG$43=""Gráfico de barras"",{""charttype"",""column"";""highcolor"",""red""},{""chartype"",""line""}))))"),"") | AJ46: TRUE | AL46: TRUE | AU46: 3 | AV46: LUCRO DIA % | AW46: lucro_dia_pct | AX46: ="order by Col"&MATCH(AW46,portfolio.!$A$3:$BO$3,0)&" "&IFERROR(VLOOKUP($M$41,$AV$57:$AX$58,3, FALSE),"") -> order by Col42 asc | AY46: 3 | BG46: 3 | BO46: 3 | BV46: =IF(AND(BT46="",BU46=""),0,IF(BT46="",BU46,BT46)) -> 0 | BW46: =IF(BV46=0,"",BV46) | BX46: 3 | BZ46: 0 | CA46: 0 | CR46: =if(AV8,"EXPOSIÇÃO POR CARTEIRA","") | CS46: select Col4, Col5 where Col5>0 and Col4 is not null | CU46: 3 | CV46: CARTEIRAS | CW46: =IFERROR(__xludf.DUMMYFUNCTION("IFERROR(query({$Q$20:$AL$20},""select Col""&MATCH(CZ46,$Q$21:$AL$21,0)))"),"") | DB46: =IFERROR(DG46/$DG$63,"") | DC46: =IFERROR(DB46/SUM($DB$44:$DB$53),"") | DD46: {=IF(NOT($AV$8),"",IF(CZ46="","",VLOOKUP(CZ46,config.carteiras!$C$9:$D$23,2,FALSE)))} | DE46: =IF($CZ46="","",DF46-DK46-DJ46) | DF46: {=IF($CZ46="","",VLOOKUP($CZ46,carteiras..!$B$2:$I$16,2,FALSE))} | DG46: {=IF($CZ46="","",VLOOKUP($CZ46,carteiras..!$B$2:$I$16,3,FALSE))} | DH46: {=IF($CZ46="","",VLOOKUP($CZ46,carteiras..!$B$2:$I$16,4,FALSE))} | DI46: =IF($CZ46="","",IFERROR(DH46/DF46,0)) | DJ46: {=IF($CZ46="","",VLOOKUP($CZ46,carteiras..!$B$2:$I$16,5,FALSE))} | DK46: {=IF($CZ46="","",VLOOKUP($CZ46,carteiras..!$B$2:$I$16,6,FALSE))} | DL46: =IF(ConfigOn,DG46-DF46,0) -> 0 | DM46: =IF($CZ46="","",SUM(DJ46:DL46)) | DN46: {=IF($CZ46="","",VLOOKUP($CZ46,carteiras..!$B$2:$I$16,7,FALSE))} | DO46: {=IF($CZ46="","",VLOOKUP($CZ46,carteiras..!$B$2:$I$16,8,FALSE))} | DP46: 2
B47: =IFERROR(__xludf.DUMMYFUNCTION("IF(B$43="""","""",IF($AZ47="""","""",IFERROR(Query({CarteirasAtivos},""Select Col3 where Col1 = '""&$AZ47&""'and Col2 = '""&S$21&""'""))))"),"") | C47: =IFERROR(__xludf.DUMMYFUNCTION("IF(C$43="""","""",IF($AZ47="""","""",IFERROR(Query({CarteirasAtivos},""Select Col3 where Col1 = '""&$AZ47&""'and Col2 = '""&T$21&""'""))))"),"") | D47: =IFERROR(__xludf.DUMMYFUNCTION("IF(D$43="""","""",IF($AZ47="""","""",IFERROR(Query({CarteirasAtivos},""Select Col3 where Col1 = '""&$AZ47&""'and Col2 = '""&U$21&""'""))))"),"") | E47: =IFERROR(__xludf.DUMMYFUNCTION("IF(E$43="""","""",IF($AZ47="""","""",IFERROR(Query({CarteirasAtivos},""Select Col3 where Col1 = '""&$AZ47&""'and Col2 = '""&V$21&""'""))))"),"") | F47: =IFERROR(__xludf.DUMMYFUNCTION("IF(F$43="""","""",IF($AZ47="""","""",IFERROR(Query({CarteirasAtivos},""Select Col3 where Col1 = '""&$AZ47&""'and Col2 = '""&W$21&""'""))))"),"") | G47: =IFERROR(__xludf.DUMMYFUNCTION("IF(G$43="""","""",IF($AZ47="""","""",IFERROR(Query({CarteirasAtivos},""Select Col3 where Col1 = '""&$AZ47&""'and Col2 = '""&X$21&""'""))))"),"") | H47: =IFERROR(__xludf.DUMMYFUNCTION("IF(H$43="""","""",IF($AZ47="""","""",IFERROR(Query({CarteirasAtivos},""Select Col3 where Col1 = '""&$AZ47&""'and Col2 = '""&Y$21&""'""))))"),"") | I47: =IFERROR(__xludf.DUMMYFUNCTION("IF(I$43="""","""",IF($AZ47="""","""",IFERROR(Query({CarteirasAtivos},""Select Col3 where Col1 = '""&$AZ47&""'and Col2 = '""&Z$21&""'""))))"),"") | J47: =IFERROR(__xludf.DUMMYFUNCTION("IF(J$43="""","""",IF($AZ47="""","""",IFERROR(Query({CarteirasAtivos},""Select Col3 where Col1 = '""&$AZ47&""'and Col2 = '""&AA$21&""'""))))"),"") | K47: =IFERROR(__xludf.DUMMYFUNCTION("IF(K$43="""","""",IF($AZ47="""","""",IFERROR(Query({CarteirasAtivos},""Select Col3 where Col1 = '""&$AZ47&""'and Col2 = '""&AB$21&""'""))))"),"") | L47: 4 | W47: =IFERROR(__xludf.DUMMYFUNCTION("IF(M47="""","""",sparkline(IFERROR(BF47*100/MAX($BF$44:$BF$153),0),{""charttype"",""bar"";""max"",100;""color1"",IF(BD47>=0,""#4760a5"",""red"")}))"),"") | AG47: =IFERROR(__xludf.DUMMYFUNCTION("IF($M47="""","""",IFERROR(sparkline(query(GOOGLEFINANCE($AZ47,""price"",TODAY()-$AF$43,TODAY(),1),""select Col2 label Col2 ''""),IF($AG$43=""Gráfico de barras"",{""charttype"",""column"";""highcolor"",""red""},{""chartype"",""line""}))))"),"") | AJ47: TRUE | AL47: TRUE | AU47: 4 | AV47: LUCRO ABERTO | AW47: lucro_aberto | AX47: ="order by Col"&MATCH(AW47,portfolio.!$A$3:$BO$3,0)&" "&IFERROR(VLOOKUP($M$41,$AV$57:$AX$58,3, FALSE),"") -> order by Col43 asc | AY47: 4 | BG47: 4 | BO47: 4 | BV47: =IF(AND(BT47="",BU47=""),0,IF(BT47="",BU47,BT47)) -> 0 | BW47: =IF(BV47=0,"",BV47) | BX47: 4 | BZ47: 0 | CA47: 0 | CR47: =if(AV8,"EXPOSIÇÃO POR PERFIL DE CARTEIRA","") | CS47: select Col1, Col2 where Col2>0 and Col1 is not null | CU47: 4 | CV47: CARTEIRAS | CW47: =IFERROR(__xludf.DUMMYFUNCTION("IFERROR(query({$Q$20:$AL$20},""select Col""&MATCH(CZ47,$Q$21:$AL$21,0)))"),"") | DB47: =IFERROR(DG47/$DG$63,"") | DC47: =IFERROR(DB47/SUM($DB$44:$DB$53),"") | DD47: {=IF(NOT($AV$8),"",IF(CZ47="","",VLOOKUP(CZ47,config.carteiras!$C$9:$D$23,2,FALSE)))} | DE47: =IF($CZ47="","",DF47-DK47-DJ47) | DF47: {=IF($CZ47="","",VLOOKUP($CZ47,carteiras..!$B$2:$I$16,2,FALSE))} | DG47: {=IF($CZ47="","",VLOOKUP($CZ47,carteiras..!$B$2:$I$16,3,FALSE))} | DH47: {=IF($CZ47="","",VLOOKUP($CZ47,carteiras..!$B$2:$I$16,4,FALSE))} | DI47: =IF($CZ47="","",IFERROR(DH47/DF47,0)) | DJ47: {=IF($CZ47="","",VLOOKUP($CZ47,carteiras..!$B$2:$I$16,5,FALSE))} | DK47: {=IF($CZ47="","",VLOOKUP($CZ47,carteiras..!$B$2:$I$16,6,FALSE))} | DL47: =IF(ConfigOn,DG47-DF47,0) -> 0 | DM47: =IF($CZ47="","",SUM(DJ47:DL47)) | DN47: {=IF($CZ47="","",VLOOKUP($CZ47,carteiras..!$B$2:$I$16,7,FALSE))} | DO47: {=IF($CZ47="","",VLOOKUP($CZ47,carteiras..!$B$2:$I$16,8,FALSE))} | DP47: 2
...

Sheet summary
A1: ='portfólio'!AV7 -> FALSE | B1: =HYPERLINK("bit.ly/dlombelloplanilhas","dlombello®planilhas "&leiame!B6) -> dlombello®planilhas v6.4.02 | H1: painel resumo e indicadores
B4: PANORAMA DO DIA | H4: PORTFÓLIO | O4: RENTABILIDADE DAS CARTEIRAS (TEMPO REAL)
B5: =NOW() -> 46092.901
B6: IBOVESPA | D6: gráfico últimos 10 dias | H6: RENDA FIXA | J6: RENDA VARIÁVEL | L6: TOTAL INVESTIDO
B7: =IFERROR(TEXT(IBOVPRICE,"#,##0.00"),"") -> 183.969,34 | D7: =TEXT(IBOVCHANGE,"#,##0.00")&" ("&TEXT(IBOVCHANGEPCT,"#,##0.00")&"%)" -> 522,34 (0,28%) | H7: FX. CAIXA | I7: MERCADO | J7: FX. CAIXA | K7: MERCADO | L7: FX. CAIXA | M7: MERCADO
B8: =IFERROR(__xludf.DUMMYFUNCTION("IF(NOT(ConfigOn),"""",IFERROR(SPARKLINE(IBOVCHANGEHISTORICO,{""charttype"",""column"";""negcolor"",""red""}),""Dados não disponíveis no momento""))"),"") | H8: =config.books!BQ22 -> 0 | I8: =config.books!BR22 | J8: =config.books!BQ23 -> 0 | K8: =config.books!BR23 | L8: ='portfólio'!Q14 | M8: ='portfólio'!Q15
H9: =config.books!BS22 | J9: =config.books!BS23 | L9: =IF(M8=0,"",100%) -> 1
B11: IFIX | D11: gráfico últimos 10 dias | H11: RESULTADO BRUTO
B12: =IFERROR(TEXT(IFIXPRICE,"#,##0.00"),"") -> 3.873,59 | D12: =TEXT(IFIXCHANGE,"#,##0.00")&" ("&TEXT(IFIXCHANGEPCT,"0.00")&"%)" -> -2,86 (-0,07%) | H12: FUNDOS E RF | I12: PROVENTOS | J12: TRADES | K12: ABERTO | L12: LUCRO TOTAL
B13: =IFERROR(__xludf.DUMMYFUNCTION("IF(NOT(ConfigOn),"""",IFERROR(SPARKLINE(IFIXCHANGEHISTORICO,{""charttype"",""column"";""negcolor"",""red""}),""Dados não disponíveis no momento""))"),"") | H13: =config.books!BT22 | I13: =config.books!BT18+config.books!BU18+config.books!BY18+config.books!CA18 -> 0 | J13: =config.books!BR18+config.books!BS18+config.books!BX18+config.books!BZ18+config.books!CB18+config.books!CC18 -> 0 | K13: =config.books!BT23-J13-I13 -> 0 | L13: ='portfólio'!DM63 -> 0
H14: =IFERROR(H13/L8,"") | I14: =IFERROR(I13/L8,"") | J14: =IFERROR(J13/L8,"") | K14: =IFERROR(K13/L8,"") | L14: =IFERROR(L13/L8,"")
B16: LUCRO DO DIA | H16: Rentabilidade do Porfólio | I16: ='portfólio'!DN63 -> -0.0014149368 | J16: INDICADORES ECONÔMICOS | O16: EXPOSIÇÃO POR BOOK
B17: ='portfólio'!Q30 | E17: BOLSA | F17: TOTAL | H17: MÊS | J17: IBOV | K17: IFIX | L17: CDI | M17: IPCA
E18: ='portfólio'!R31 | F18: ='portfólio'!Q31 | H18: 44682 | J18: 0.032212911 | K18: 0.0026269942 | L18: 0.0103 | M18: #NUM!
H19: 44652 | J19: -0.10102584 | K19: 0.011903038 | L19: 0.0083 | M19: 0.0106
B20: MAIORES LUCROS/PREJUÍZOS HOJE | H20: 44621 | J20: 0.060605257 | K20: 0.014161965 | L20: 0.0093 | M20: 0.0162
H21: 44593 | J21: 0.0067089013 | K21: -0.012881185 | L21: 0.0076 | M21: 0.0101
H22: 44562 | J22: 0.072179504 | K22: 0.019202754 | L22: 0.0073 | M22: 0.0054
H23: 44531 | J23: 0.02852377 | K23: 0.072035662 | L23: 0.0077 | M23: 0.0073
H24: 44501 | J24: -0.015323523 | K24: -0.050140518 | L24: 0.0059 | M24: 0.0095
H25: 44470 | J25: -0.067382117 | K25: -0.014725648 | L25: 0.0049 | M25: 0.0125
H26: 44440 | J26: -0.065683906 | K26: -0.012426178 | L26: 0.0044 | M26: 0.0116
H27: 44409 | J27: -0.024794542 | K27: -0.026301998 | L27: 0.0043 | M27: 0.0087
H28: 44378 | J28: -0.039439441 | K28: 0.02512986 | L28: 0.0036 | M28: 0.0096
H29: 44348 | J29: 0.0046428345 | K29: -0.021860776 | L29: 0.0031 | M29: 0.0053
H30: 44317 | J30: 0.061584268 | K30: -0.015619594 | L30: 0.0027 | M30: 0.0083
H31: 44287 | J31: 0.019376854 | K31: 0.0050513389 | L31: 0.0021 | M31: 0.0031
H32: 44256 | J32: 0.059971827 | K32: -0.013774324 | L32: 0.002 | M32: 0.0093
H33: 44228 | J33: -0.051479652 | K33: 0.0024588029 | L33: 0.0013 | M33: 0.0086
B36: CHANGE
B37: IBOV | C37: IFIX
B38: =IBOVCHANGE -> 522.34 | C38: =IFIXCHANGE -> -2.86
B42: Carteiras | D42: Reduz | E42: %
B43: {=CarteirasListaCriadasComTotal} -> TODAS AS CARTEIRAS | D43: TOTAL CARTEIRAS | E43: {={'portfólio'!DN60;'portfólio'!DN44:DN53}} -> -
D44: {=CarteirasListaCriadasAbreviada}

Sheet rendimentos
B1: =HYPERLINK("bit.ly/dlombelloplanilhas","dlombello®planilhas "&leiame!B6) -> dlombello®planilhas v6.4.02 | E1: FALSE | F1: painel proventos recebidos | AB1: ATIIVADA?
AB2: =AND($E$1,ConfigOn) -> FALSE
B4: Filtro por período | G4: CARTEIRAS | K4: FALSE | L4: FALSE | M4: FALSE | N4: FALSE | O4: FALSE | P4: FALSE | Q4: FALSE | R4: FALSE | S4: FALSE | T4: FALSE | U4: FALSE | V4: FALSE | W4: FALSE | X4: FALSE | Y4: FALSE | Z4: FALSE | AB4: Combobox selecao mes/ano | AD4: Para selecao na query
B5: =IF(AND(B7="",D7=""),"Digite ano e mês ou digite data de início e fim","Período "&TEXT(AD6,"dd.mm.yyyy")&" a "&TEXT(AE6,"dd.mm.yyyy")) -> Digite ano e mês ou digite data de início e fim | K5: {=TRANSPOSE(CarteirasListaCriadasComTotal)} -> TODAS AS CARTEIRAS | AB5: Data inicial | AC5: Data final | AD5: Data Inicial | AE5: Data final
B6: Ano | C6: Mes | D6: Data inicio | E6: Data fim | AB6: =date(B7,if(C7="Janeiro",1,if(C7="Fevereiro",2,if(C7="Marco",3,if(C7="Abril",4,if(C7="Maio",5,if(C7="Junho",6,if(C7="Julho",7,if(C7="Agosto",8,if(C7="Setembro",9,if(C7="Outubro",10,if(C7="Novembro",11,12))))))))))),1) -> 336 | AC6: =eomonth(AB6,0) -> 366 | AD6: =if(D7="",AB6,D7) -> 336 | AE6: =if(D7="",AC6,E7) -> 366
B8: Ordenar por: | D8: Data | G8: Média mensal histórica | I8: Últimos 12 meses | J8: =eomonth(today(),-1) -> 46081 | K8: =eomonth(today(),-2) -> 46053 | L8: =eomonth(today(),-3) -> 46022 | M8: =eomonth(today(),-4) -> 45991 | N8: =eomonth(today(),-5) -> 45961 | O8: =eomonth(today(),-6) -> 45930 | P8: =eomonth(today(),-7) -> 45900 | Q8: =eomonth(today(),-8) -> 45869 | R8: =eomonth(today(),-9) -> 45838 | S8: =eomonth(today(),-10) -> 45808 | T8: =eomonth(today(),-11) -> 45777 | U8: =eomonth(today(),-12) -> 45747 | V8: =year(today()) -> 2026 | W8: =year(today())-1 -> 2025 | X8: =year(today())-2 -> 2024 | Y8: =year(today())-3 -> 2023 | Z8: =year(today())-4 -> 2022 | AB8: ENCERRADOS
B9: Ativo | C9: Data | D9: Evento | E9: Valor | AD9: CHECKS | AE9: QUERY CARTEIRA
E10: =sum(E11:E310) -> 0 | G10: ATIVO | H10: =SUM(H11:H310) -> 0 | I10: =sum(I11:I310) -> 0 | J10: =sum(J11:J310) -> 0 | K10: =sum(K11:K310) -> 0 | L10: =sum(L11:L310) -> 0 | M10: =sum(M11:M310) -> 0 | N10: =sum(N11:N310) -> 0 | O10: =sum(O11:O310) -> 0 | P10: =sum(P11:P310) -> 0 | ... Z10: =sum(Z11:Z310) -> 0 | AD10: =IFERROR(__xludf.DUMMYFUNCTION("IFERROR("" (Col2 = '""&join(""' or Col2 = '"",filter(carteiras.!AE6:AE20, AD12:AD26))&""') "")"),"") | AE10: =if(AND(AD10="",AD11=false),"Col2 = ''",AD10)
